Workbook

Sheet Escenario Base
A1: Concepto | B1: Valor | C1: Notas | D1: Valor Sin IVA | E1: IVA | F1: 0.13 | I1: 0 | J1: 1 | K1: 2 | L1: 3 | M1: 4 | N1: 5 | O1: 6 | P1: 7 | Q1: 8
A2: Maquinaria | B2: 80000 | C2: Monto bruto IVA | D2: =+B2-B2*F$1 -> 69600 | E2: =+B2-D2 -> 10400 | H2: Activo Fijo | I2: =+SUM(I3:I5) -> -99000
A3: Obras civiles | B3: 20000 | C3: Monto bruto IVA | D3: =+B3-B3*F$1 -> 17400 | E3: =+B3-D3 -> 2600 | H3: Maquinaria | I3: =-D2 -> -69600
A4: Terreno | B4: 12000 | D4: =+B4 -> 12000 | E4: 0 | H4: Obras Civiles | I4: =-D3 -> -17400
A5: Ingeniería del proyecto | B5: 10000 | C5: Monto bruto IVA | D5: =+B5-B5*F$1 -> 8700 | E5: =+B5-D5 -> 1300 | H5: Terreno | I5: =-D4 -> -12000
A6: Gastos preoperacionales | B6: 5000 | D6: =+B6 -> 5000 | E6: 0 | H6: Activo Diferido | I6: =+SUM(I7:I8) -> -13700
A7: Capital de trabajo | B7: 0.1 | C7: De las ventas brutas | H7: Ingeniería del proyecto | I7: =-D5 -> -8700
A8: Vida útil maquinaria | B8: 8 | C8: Años | H8: Gastos preoperacionales | I8: =-B6 -> -5000
A9: Vida contable maquinaria | B9: 5 | C9: Años | H9: Capital de trabajo | I9: =+I10 -> -7500 | J9: =+J10-I10 -> -750 | K9: =+K10-J10 -> -1500 | L9: =+L10-K10 -> -750 | M9: 0 | N9: 0 | O9: 0 | P9: 0 | Q9: 0
A10: Vida contable obras civiles | B10: 40 | C10: Años | H10: Capital de trabajo Necesario | I10: =+J19/0.87*$B$7*-1 -> -7500 | J10: =+K19/0.87*$B$7*-1 -> -8250 | K10: =+L19/0.87*$B$7*-1 -> -9750 | L10: =+M19/0.87*$B$7*-1 -> -10500 | M10: 0 | N10: 0 | O10: 0 | P10: 0 | Q10: 0
A12: Amortización inversión diferida | B12: 4 | C12: Años | H12: Valor Terminal | Q12: =+SUM(Q13:Q16)-L10 -> 41640
A13: Capacidad producción | B13: 30000 | C13: Unidades/año | H13: Valor residual maquinaria | Q13: =B2*0.1*87% -> 6960
A14: Utilización año 1 | B14: 0.5 | H14: Valor residual obras civiles | Q14: =-I4--I4*(8/40) -> 13920
A15: Utilización año 2 | B15: 0.65 | H15: Valor residual terreno | Q15: =+B4 -> 12000
A16: Utilización año 3 | B16: 0.9 | H16: Efecto impositivo | Q16: =+Q13*-25% -> -1740
A18: Utilización año 4+ | B18: 1 | H18: Flujo de inversion | I18: =I12+I9+I2+I6 -> -120200 | J18: =J12+J9+J2+J6 -> -750 | K18: =K12+K9+K2+K6 -> -1500 | L18: =L12+L9+L2+L6 -> -750 | M18: =M12+M9+M2+M6 -> 0 | N18: =N12+N9+N2+N6 -> 0 | O18: =O12+O9+O2+O6 -> 0 | P18: =P12+P9+P2+P6 -> 0 | Q18: =Q12+Q9+Q2+Q6 -> 41640
A19: Precio venta | B19: 5 | C19: Por unidad | D19: =+B19-B19*F$1 -> 4.35 | E19: =+B19-D19 -> 0.65 | H19: Ventas | J19: {=+TRANSPOSE($C$31:$C$38)*$D$19} -> 65250 | K19: 71775 | L19: 84825 | M19: 91350 | N19: 110925 | O19: 130500 | P19: 130500 | Q19: 130500
A20: Costo variable | B20: 1.7 | C20: 100% con crédito fiscal | D20: =+B20-B20*F$1 -> 1.479 | H20: Costo Variable | J20: =(+$D$20*B14*$B$13)*-1 -> -22185 | K20: =(+$D$20*B15*$B$13)*-1 -> -28840.5 | L20: =(+$D$20*B16*$B$13)*-1 -> -39933 | M20: =(+$D$20*$B$18*$B$13)*-1 -> -44370 | N20: =(+$D$20*$B$18*$B$13)*-1 -> -44370 | O20: =(+$D$20*$B$18*$B$13)*-1 -> -44370 | P20: =(+$D$20*$B$18*$B$13)*-1 -> -44370 | Q20: =(+$D$20*$B$18*$B$13)*-1 -> -44370
A21: Costo fijo | B21: 10000 | C21: 70% tiene CF | D21: =B21-B21*70%*F$1 -> 9090 | E21: =+B21-D21 -> 910 | H21: Costo Fijo | J21: =(+$D$21)*-1 -> -9090 | K21: =(+$D$21)*-1 -> -9090 | L21: =(+$D$21)*-1 -> -9090 | M21: =(+$D$21)*-1 -> -9090 | N21: =(+$D$21)*-1 -> -9090 | O21: =(+$D$21)*-1 -> -9090 | P21: =(+$D$21)*-1 -> -9090 | Q21: =(+$D$21)*-1 -> -9090
A22: Gasto administración | B22: 6000 | C22: 60% tiene CF | D22: =B22-B22*60%*F$1 -> 5532 | E22: =+B22-D22 -> 468 | H22: Gastos de Admin | J22: =+$D$22*-1 -> -5532 | K22: =+$D$22*-1 -> -5532 | L22: =+$D$22*-1 -> -5532 | M22: =+$D$22*-1 -> -5532 | N22: =+$D$22*-1 -> -5532 | O22: =+$D$22*-1 -> -5532 | P22: =+$D$22*-1 -> -5532 | Q22: =+$D$22*-1 -> -5532
A23: Rentabilidad requerida | B23: 0.1 | H23: Depreciación | J23: =-Depreciacion!B4 -> -14355 | K23: =-Depreciacion!C4 -> -14355 | L23: =-Depreciacion!D4 -> -14355 | M23: =-Depreciacion!E4 -> -14355 | N23: =-Depreciacion!F4 -> -14355 | O23: =-Depreciacion!G4 -> -435 | P23: =-Depreciacion!H4 -> -435 | Q23: =-Depreciacion!I4 -> -435
A24: Periodo recuperación máximo | B24: 8 | C24: Años | H24: Amortización | J24: =-Depreciacion!B9 -> -3425 | K24: =-Depreciacion!C9 -> -3425 | L24: =-Depreciacion!D9 -> -3425 | M24: =-Depreciacion!E9 -> -3425 | N24: =-Depreciacion!F9 -> 0 | O24: =-Depreciacion!G9 -> 0 | P24: =-Depreciacion!H9 -> 0 | Q24: =-Depreciacion!I9 -> 0
A25: Valor residual maquinaria | B25: 0.1 | C25: Del valor bruto | H25: IT Efectivo | J25: =-IF(I27>=0,-0.03*J19/0.87,IF(-I27>J19/0.87*0.03,0,-(0.03*J19/0.87+I27)))*-1 -> -2250 | K25: =-IF(J27>=0,-0.03*K19/0.87,IF(-J27>K19/0.87*0.03,0,-(0.03*K19/0.87+J27)))*-1 -> -371.75 | L25: =-IF(K27>=0,-0.03*L19/0.87,IF(-K27>L19/0.87*0.03,0,-(0.03*L19/0.87+K27)))*-1 -> -384.8125 | M25: =-IF(L27>=0,-0.03*M19/0.87,IF(-L27>M19/0.87*0.03,0,-(0.03*M19/0.87+L27)))*-1 -> -123.70312 | N25: =-IF(M27>=0,-0.03*N19/0.87,IF(-M27>N19/0.87*0.03,0,-(0.03*N19/0.87+M27)))*-1 -> -211.42578 | O25: =-IF(N27>=0,-0.03*O19/0.87,IF(-N27>O19/0.87*0.03,0,-(0.03*O19/0.87+N27)))*-1 -> 0 | P25: =-IF(O27>=0,-0.03*P19/0.87,IF(-O27>P19/0.87*0.03,0,-(0.03*P19/0.87+O27)))*-1 -> 0 | Q25: =-IF(P27>=0,-0.03*Q19/0.87,IF(-P27>Q19/0.87*0.03,0,-(0.03*Q19/0.87+P27)))*-1 -> 0
A26: Valor residual obras civiles | B26: Valor contable | H26: UAI | J26: =+SUM(J19:J25) -> 8413 | K26: =+SUM(K19:K25) -> 10160.75 | L26: =+SUM(L19:L25) -> 12105.188 | M26: =+SUM(M19:M25) -> 14454.297 | N26: =+SUM(N19:N25) -> 37366.574 | O26: =+SUM(O19:O25) -> 71073 | P26: =+SUM(P19:P25) -> 71073 | Q26: =+SUM(Q19:Q25) -> 71073
A27: Valor residual terreno | B27: Valor compra | H27: IUE | J27: =+J26*-0.25 -> -2103.25 | K27: =+K26*-0.25 -> -2540.1875 | L27: =+L26*25%*-1 -> -3026.2969 | M27: =+M26*25%*-1 -> -3613.5742 | N27: =+N26*25%*-1 -> -9341.6436 | O27: =+O26*25%*-1 -> -17768.25 | P27: =+P26*25%*-1 -> -17768.25 | Q27: =+Q26*25%*-1 -> -17768.25
H28: UDI | J28: =+J26+J27 -> 6309.75 | K28: =+K26+K27 -> 7620.5625 | L28: =+L26+L27 -> 9078.8906 | M28: =+M26+M27 -> 10840.723 | N28: =+N26+N27 -> 28024.931 | O28: =+O26+O27 -> 53304.75 | P28: =+P26+P27 -> 53304.75 | Q28: =+Q26+Q27 -> 53304.75
H29: Depreciación | J29: =-J23 -> 14355 | K29: =-K23 -> 14355 | L29: =-L23 -> 14355 | M29: =-M23 -> 14355 | N29: =-N23 -> 14355 | O29: =-O23 -> 435 | P29: =-P23 -> 435 | Q29: =-Q23 -> 435
A30: Año | B30: Utilización | C30: Producción unidades | H30: Amortización | J30: =-J24 -> 3425 | K30: =-K24 -> 3425 | L30: =-L24 -> 3425 | M30: =-M24 -> 3425 | N30: =-N24 -> 0 | O30: =-O24 -> 0 | P30: =-P24 -> 0 | Q30: =-Q24 -> 0
A31: 1 | B31: 0.5 | C31: =+B31*$B$13 -> 15000 | E31: =0.1/5 -> 0.02 | H31: Flujo de operación | J31: =+J28+J29+J30 -> 24089.75 | K31: =+K28+K29+K30 -> 25400.562 | L31: =+L28+L29+L30 -> 26858.891 | M31: =+M28+M29+M30 -> 28620.723 | N31: =+N28+N29+N30 -> 42379.931 | O31: =+O28+O29+O30 -> 53739.75 | P31: =+P28+P29+P30 -> 53739.75 | Q31: =+Q28+Q29+Q30 -> 53739.75
A32: 2 | B32: 0.55 | C32: =+B32*$B$13 -> 16500
A33: 3 | B33: 0.65 | C33: =+B33*$B$13 -> 19500 | H33: Flujo de caja libre | I33: =+I18+I31 -> -120200 | J33: =+J18+J31 -> 23339.75 | K33: =+K18+K31 -> 23900.562 | L33: =+L18+L31 -> 26108.891 | M33: =+M18+M31 -> 28620.723 | N33: =+N18+N31 -> 42379.931 | O33: =+O18+O31 -> 53739.75 | P33: =+P18+P31 -> 53739.75 | Q33: =+Q18+Q31 -> 95379.75
A34: 4 | B34: 0.7 | C34: =+B34*$B$13 -> 21000 | H34: Flujos descontados | I34: =+I33 -> -120200 | J34: =+J33/(1+10%)^J1 -> 21217.955 | K34: =+K33/(1+10%)^K1 -> 19752.531 | L34: =+L33/(1+10%)^L1 -> 19615.996 | M34: =+M33/(1+10%)^M1 -> 19548.339 | N34: =+N33/(1+10%)^N1 -> 26314.603 | O34: =+O33/(1+10%)^O1 -> 30334.688 | P34: =+P33/(1+10%)^P1 -> 27576.989 | Q34: =+Q33/(1+10%)^Q1 -> 44495.357
A35: 5 | B35: 0.85 | C35: =+B35*$B$13 -> 25500 | I35: =+I34 -> -120200 | J35: =+J34+I35 -> -98982.045 | K35: =+K34+J35 -> -79229.514 | L35: =+L34+K35 -> -59613.519 | M35: =+M34+L35 -> -40065.18 | N35: =+N34+M35 -> -13750.577 | O35: =+O34+N35 -> 16584.111 | P35: =+P34+O35 -> 44161.1 | Q35: =+Q34+P35 -> 88656.457
A36: 6 | B36: 1 | C36: =+B36*$B$13 -> 30000 | H36: Liquidacion Anticipada de Activos | J36: 0.6 | K36: 0.5 | L36: 0.4 | M36: 0.3 | N36: 0.25 | O36: 0.2 | P36: 0.15 | Q36: =10%*(8/Q1)^2 -> 0.1
A37: 7 | B37: 1 | C37: =+B37*$B$13 -> 30000 | H37: Liquidacion Anticipada de Maquinaria | J37: =+J36*$D$2 -> 41760 | K37: =+K36*$D$2 -> 34800 | L37: =+L36*$D$2 -> 27840 | M37: =+M36*$D$2 -> 20880 | N37: =+N36*$D$2 -> 17400 | O37: =+O36*$D$2 -> 13920 | P37: =+P36*$D$2 -> 10440 | Q37: =+Q36*$D$2 -> 6960
A38: 8 | B38: 1 | C38: =+B38*$B$13 -> 30000 | H38: Liquidacion Anticipada de Obras Civiles | J38: =-$I4--$I4*(J1/40) -> 16965 | K38: =-$I4--$I4*(K1/40) -> 16530 | L38: =-$I4--$I4*(L1/40) -> 16095 | M38: =-$I4--$I4*(M1/40) -> 15660 | N38: =-$I4--$I4*(N1/40) -> 15225 | O38: =-$I4--$I4*(O1/40) -> 14790 | P38: =-$I4--$I4*(P1/40) -> 14355 | Q38: =-$I4--$I4*(Q1/40) -> 13920
H39: Liquidacion Anticipada de Terreno | J39: =+B4 -> 12000 | K39: =+J39 -> 12000 | L39: =+K39 -> 12000 | M39: =+L39 -> 12000 | N39: =+M39 -> 12000 | O39: =+N39 -> 12000 | P39: =+O39 -> 12000 | Q39: =+P39 -> 12000
H40: Liquidacion Anticipada Capital de Trabajo | J40: =-IF(J9<>0,J9,LOOKUP(2,1/($I$9:$Q$9<>0),$I$9:$Q$9))*J36 -> 450 | K40: =-IF(K9<>0,K9,LOOKUP(2,1/($I$9:$Q$9<>0),$I$9:$Q$9))*K36 -> 750 | L40: =-IF(L9<>0,L9,LOOKUP(2,1/($I$9:$Q$9<>0),$I$9:$Q$9))*L36 -> 300 | M40: =-IF(M9<>0,M9,LOOKUP(2,1/($I$9:$Q$9<>0),$I$9:$Q$9))*M36 -> 225 | N40: =-IF(N9<>0,N9,LOOKUP(2,1/($I$9:$Q$9<>0),$I$9:$Q$9))*N36 -> 187.5 | O40: =-IF(O9<>0,O9,LOOKUP(2,1/($I$9:$Q$9<>0),$I$9:$Q$9))*O36 -> 150 | P40: =-IF(P9<>0,P9,LOOKUP(2,1/($I$9:$Q$9<>0),$I$9:$Q$9))*P36 -> 112.5 | Q40: =-IF(Q9<>0,Q9,LOOKUP(2,1/($I$9:$Q$9<>0),$I$9:$Q$9))*Q36 -> 75
A42: Concepto | B42: Tipo | C42: Monto | D42: Base
A43: Precio venta | B43: Unitario | C43: 5 | D43: por unidad
...

Sheet Flujo de Caja
A1: Concepto | B1: Valor | C1: Notas | D1: Valor Sin IVA | E1: IVA → | F1: 0.13 | H1: Años → | I1: 0 | J1: 1 | K1: 2 | L1: 3 | M1: 4 | N1: 5 | O1: 6 | P1: 7 | Q1: 8
A2: Maquinaria | B2: 80000 | C2: Monto bruto IVA | D2: =+B2-B2*F$1 -> 69600 | E2: =+B2-D2 -> 10400 | H2: Activo Fijo | I2: =+SUM(I3:I5) -> -99000 | S2: Tasa de Descuento | T2: =+B23 -> 0.14 | AA2: -16972.14 | AB2: 0.0001 | AC2: 9 | AD2: 4.9483602 | AE2: 2.1843831 | AF2: 1
A3: Obras civiles | B3: 20000 | C3: Monto bruto IVA | D3: =+B3-B3*F$1 -> 17400 | E3: =+B3-D3 -> 2600 | H3: Maquinaria | I3: =-D2 -> -69600 | S3: VAN Sin escenarios de quiebre | T3: 15866.905 | AA3: 16757.36 | AB3: 0.0001 | AC3: 8 | AD3: 5.1056029 | AE3: 2.2325484 | AF3: 1
A4: Terreno | B4: 12000 | D4: =+B4 -> 12000 | E4: 0 | H4: Obras Civiles | I4: =-D3 -> -17400 | S4: =+H47 -> TIR | T4: =+I47 -> 0.17309667 | AA4: 35447.31 | AB4: 0.0001 | AC4: 7 | AD4: 4.8169821 | AE4: 2.1675282 | AF4: 1
A5: Ingeniería del proyecto | B5: 10000 | C5: Monto bruto IVA | D5: =+B5-B5*F$1 -> 8700 | E5: =+B5-D5 -> 1300 | H5: Terreno | I5: =-D4 -> -12000 | S5: VAN Simulado | T5: =+I46 -> 18211.085 | AA5: 7182.49 | AB5: 0.0001 | AC5: 8 | AD5: 4.9263299 | AE5: 2.058931 | AF5: 1
A6: Gastos preoperacionales | B6: 5000 | D6: =+B6 -> 5000 | E6: 0 | H6: Activo Diferido | I6: =+SUM(I7:I8) -> -13700 | S6: =+H49 -> Periodo de recuperacion | T6: =+I49 -> 8 | AA6: -1866.61 | AB6: 0.0001 | AC6: 9 | AD6: 4.9355586 | AE6: 2.1793856 | AF6: 1
A7: Capital de trabajo | B7: 0.1 | C7: De las ventas brutas | H7: Ingeniería del proyecto | I7: =-D5 -> -8700 | S7: Tiempo de Vida del Proyecto | T7: 8 | AA7: 18353.38 | AB7: 0.0001 | AC7: 8 | AD7: 4.9774981 | AE7: 2.2076876 | AF7: 1
A8: Vida útil maquinaria | B8: 8 | C8: Años | H8: Gastos preoperacionales | I8: =-B6 -> -5000 | S8: =+IF(T8="","","Éxito (VAN > 0)") -> Éxito (VAN > 0) | T8: =IFERROR(COUNTIF(AA:AA,">"&0)/COUNT(AA:AA),"") -> 0.8052 | AA8: 10194.93 | AB8: 0.0001 | AC8: 8 | AD8: 5.0521247 | AE8: 2.1716812 | AF8: 1
A9: Vida contable maquinaria | B9: 5 | C9: Años | H9: Capital de trabajo | I9: =+I10 -> -7500 | J9: =+J10-I10 -> -750 | K9: =+K10-J10 -> -1500 | L9: =+L10-K10 -> -750 | M9: 0 | N9: 0 | O9: 0 | P9: 0 | Q9: 0 | S9: =+IF(T9="","","Fracaso (VAN < 0)") -> Fracaso (VAN < 0) | T9: =IF(T8="","",1-T8) -> 0.1948 | AA9: 18444.12 | AB9: 0.0001 | AC9: 8 | AD9: 4.9399346 | AE9: 2.1864154 | AF9: 1
A10: Vida contable obras civiles | B10: 40 | C10: Años | H10: Capital de trabajo Necesario | I10: =+J19/0.87*$B$7*-1 -> -7500 | J10: =+K19/0.87*$B$7*-1 -> -8250 | K10: =+L19/0.87*$B$7*-1 -> -9750 | L10: =+M19/0.87*$B$7*-1 -> -10500 | M10: 0 | N10: 0 | O10: 0 | P10: 0 | Q10: 0 | S10: =+IF(T10="","","Supervivencia") -> Supervivencia | T10: =IFERROR(COUNTIF(AF:AF,1)/COUNT(AF:AF),"") -> 0.972 | AA10: 16100.26 | AB10: 0.0001 | AC10: 8 | AD10: 5.0789104 | AE10: 2.1489271 | AF10: 1
S11: =+IF(T11="","","Quiebre") -> Quiebre | T11: =IF(T10="","",1-T10) -> 0.028 | AA11: 644.14 | AB11: 0.0001 | AC11: 8 | AD11: 5.0166402 | AE11: 2.2974518 | AF11: 1
A12: Amortización inversión diferida | B12: 4 | C12: Años | H12: Valor Terminal | Q12: =+SUM(Q13:Q16)-L10 -> 41640 | S12: VAN Liquidacion de Activos | T12: -20878.982 | AA12: 35170.81 | AB12: 0.0001 | AC12: 7 | AD12: 4.981485 | AE12: 2.2290996 | AF12: 1
A13: Capacidad producción | B13: 30000 | C13: Unidades/año | H13: Valor residual maquinaria | Q13: =B2*0.1*87% -> 6960 | S13: VAN ESPERADO | T13: =+IF(I56=0,"⏳",I56) -> 14838.02 | AA13: 27867.71 | AB13: 0.0001 | AC13: 8 | AD13: 5.1850761 | AE13: 2.223941 | AF13: 1
A14: Utilización año 1 | B14: 0.5 | H14: Valor residual obras civiles | Q14: =-I4--I4*(8/40) -> 13920 | AA14: 20582.37 | AB14: 0.0001 | AC14: 8 | AD14: 5.0672833 | AE14: 2.1936643 | AF14: 1
A15: Utilización año 2 | B15: 0.65 | H15: Valor residual terreno | Q15: =+B4 -> 12000 | AA15: 29365.69 | AB15: 0.0001 | AC15: 7 | AD15: 5.0487723 | AE15: 2.1806128 | AF15: 1
A16: Utilización año 3 | B16: 0.9 | H16: Efecto impositivo | Q16: =+Q13*-25% -> -1740 | AA16: 14666.4 | AB16: 0.0001 | AC16: 8 | AD16: 4.9515063 | AE16: 2.1497887 | AF16: 1
AA17: 32893.54 | AB17: 0.0001 | AC17: 7 | AD17: 4.9245424 | AE17: 2.201951 | AF17: 1
A18: Utilización año 4+ | B18: 1 | H18: Flujo de inversion | I18: =I12+I9+I2+I6 -> -120200 | J18: =J12+J9+J2+J6 -> -750 | K18: =K12+K9+K2+K6 -> -1500 | L18: =L12+L9+L2+L6 -> -750 | M18: =M12+M9+M2+M6 -> 0 | N18: =N12+N9+N2+N6 -> 0 | O18: =O12+O9+O2+O6 -> 0 | P18: =P12+P9+P2+P6 -> 0 | Q18: =Q12+Q9+Q2+Q6 -> 41640 | AA18: 36704.06 | AB18: 0.0001 | AC18: 7 | AD18: 5.0847817 | AE18: 2.1503908 | AF18: 1
A19: Precio venta | B19: 5 | C19: Por unidad | D19: =+B19-B19*F$1 -> 4.35 | E19: =+B19-D19 -> 0.65 | H19: Ventas | J19: =+B31*B13*D19 -> 65250 | K19: =+B32*B13*D19 -> 71775 | L19: =+B33*B13*D19 -> 84825 | M19: =+$B$34*$B$13*$D$19 -> 91350 | N19: =+$B$35*$B$13*$D$19 -> 110925 | O19: =+$B$36*$B$13*$D$19 -> 130500 | P19: =+$B$37*$B$13*$D$19 -> 130500 | Q19: =+$B$38*$B$13*$D$19 -> 130500 | AA19: 15122.99 | AB19: 0.0001 | AC19: 8 | AD19: 5.0018497 | AE19: 2.1705393 | AF19: 1
A20: Costo variable | B20: 2.25 | C20: 100% con crédito fiscal | D20: =+B20-B20*F$1 -> 1.9575 | H20: Costo Variable | J20: =(+$D$20*B14*$B$13)*-1 -> -29362.5 | K20: =(+$D$20*B15*$B$13)*-1 -> -38171.25 | L20: =(+$D$20*B16*$B$13)*-1 -> -52852.5 | M20: =(+$D$20*$B$18*$B$13)*-1 -> -58725 | N20: =(+$D$20*$B$18*$B$13)*-1 -> -58725 | O20: =(+$D$20*$B$18*$B$13)*-1 -> -58725 | P20: =(+$D$20*$B$18*$B$13)*-1 -> -58725 | Q20: =(+$D$20*$B$18*$B$13)*-1 -> -58725 | AA20: -1558.02 | AB20: 0.0001 | AC20: 9 | AD20: 4.8268513 | AE20: 2.2404067 | AF20: 1
A21: Costo fijo | B21: 8000 | C21: 70% tiene CF | D21: =B21-B21*70%*F$1 -> 7272 | E21: =+B21-D21 -> 728 | H21: Costo Fijo | J21: =(+$D$21)*-1 -> -7272 | K21: =(+$D$21)*-1 -> -7272 | L21: =(+$D$21)*-1 -> -7272 | M21: =(+$D$21)*-1 -> -7272 | N21: =(+$D$21)*-1 -> -7272 | O21: =(+$D$21)*-1 -> -7272 | P21: =(+$D$21)*-1 -> -7272 | Q21: =(+$D$21)*-1 -> -7272 | AA21: 34716.84 | AB21: 0.0001 | AC21: 7 | AD21: 5.015347 | AE21: 2.2339408 | AF21: 1
A22: Gasto administración | B22: 5000 | C22: 60% tiene CF | D22: =B22-B22*60%*F$1 -> 4610 | E22: =+B22-D22 -> 390 | H22: Gastos de Admin | J22: =+$D$22*-1 -> -4610 | K22: =+$D$22*-1 -> -4610 | L22: =+$D$22*-1 -> -4610 | M22: =+$D$22*-1 -> -4610 | N22: =+$D$22*-1 -> -4610 | O22: =+$D$22*-1 -> -4610 | P22: =+$D$22*-1 -> -4610 | Q22: =+$D$22*-1 -> -4610 | AA22: 14501.08 | AB22: 0.0001 | AC22: 8 | AD22: 5.1154988 | AE22: 2.1632955 | AF22: 1
A23: Rentabilidad requerida | B23: 0.14 | H23: Depreciación | J23: =-Depreciacion!B4 -> -14355 | K23: =-Depreciacion!C4 -> -14355 | L23: =-Depreciacion!D4 -> -14355 | M23: =-Depreciacion!E4 -> -14355 | N23: =-Depreciacion!F4 -> -14355 | O23: =-Depreciacion!G4 -> -435 | P23: =-Depreciacion!H4 -> -435 | Q23: =-Depreciacion!I4 -> -435 | AA23: 452.54 | AB23: 0.0001 | AC23: 8 | AD23: 4.9687989 | AE23: 2.2576789 | AF23: 1
A24: Periodo recuperación máximo | B24: 8 | C24: Años | H24: Amortización | J24: =-Depreciacion!B9 -> -3425 | K24: =-Depreciacion!C9 -> -3425 | L24: =-Depreciacion!D9 -> -3425 | M24: =-Depreciacion!E9 -> -3425 | N24: =-Depreciacion!F9 -> 0 | O24: =-Depreciacion!G9 -> 0 | P24: =-Depreciacion!H9 -> 0 | Q24: =-Depreciacion!I9 -> 0 | AA24: 5931.97 | AB24: 0.0001 | AC24: 8 | AD24: 4.9897187 | AE24: 2.2053044 | AF24: 1
A25: Valor residual maquinaria | B25: 0.1 | C25: Del valor bruto | H25: IT Efectivo | J25: =-IF(I27>=0,-0.03*J19/0.87,IF(-I27>J19/0.87*0.03,0,-(0.03*J19/0.87+I27)))*-1 -> -2250 | K25: =-IF(J27>=0,-0.03*K19/0.87,IF(-J27>K19/0.87*0.03,0,-(0.03*K19/0.87+J27)))*-1 -> -1481.125 | L25: =-IF(K27>=0,-0.03*L19/0.87,IF(-K27>L19/0.87*0.03,0,-(0.03*L19/0.87+K27)))*-1 -> -2309.8438 | M25: =-IF(L27>=0,-0.03*M19/0.87,IF(-L27>M19/0.87*0.03,0,-(0.03*M19/0.87+L27)))*-1 -> -3149.8359 | N25: =-IF(M27>=0,-0.03*N19/0.87,IF(-M27>N19/0.87*0.03,0,-(0.03*N19/0.87+M27)))*-1 -> -3825 | O25: =-IF(N27>=0,-0.03*O19/0.87,IF(-N27>O19/0.87*0.03,0,-(0.03*O19/0.87+N27)))*-1 -> 0 | P25: =-IF(O27>=0,-0.03*P19/0.87,IF(-O27>P19/0.87*0.03,0,-(0.03*P19/0.87+O27)))*-1 -> 0 | Q25: =-IF(P27>=0,-0.03*Q19/0.87,IF(-P27>Q19/0.87*0.03,0,-(0.03*Q19/0.87+P27)))*-1 -> 0 | AA25: 9340.33 | AB25: 0.0001 | AC25: 8 | AD25: 4.9442107 | AE25: 2.1735981 | AF25: 1
A26: Valor residual obras civiles | B26: Valor contable | H26: UAI | J26: =+SUM(J19:J25) -> 3975.5 | K26: =+SUM(K19:K25) -> 2460.625 | L26: =+SUM(L19:L25) -> 0.65625 | M26: =+SUM(M19:M25) -> -186.83594 | N26: =+SUM(N19:N25) -> 22138 | O26: =+SUM(O19:O25) -> 59458 | P26: =+SUM(P19:P25) -> 59458 | Q26: =+SUM(Q19:Q25) -> 59458 | AA26: -9544.97 | AB26: 0.0001 | AC26: 9 | AD26: 4.8766279 | AE26: 2.1726562 | AF26: 1
A27: Valor residual terreno | B27: Valor compra | H27: IUE | J27: =+J26*-0.25 -> -993.875 | K27: =+K26*-0.25 -> -615.15625 | L27: =+L26*25%*-1 -> -0.1640625 | M27: =+M26*25%*-1 -> 46.708984 | N27: =+N26*25%*-1 -> -5534.5 | O27: =+O26*25%*-1 -> -14864.5 | P27: =+P26*25%*-1 -> -14864.5 | Q27: =+Q26*25%*-1 -> -14864.5 | AA27: 22592.38 | AB27: 0.0001 | AC27: 8 | AD27: 4.9068988 | AE27: 2.1088608 | AF27: 1
H28: UDI | J28: =+J26+J27 -> 2981.625 | K28: =+K26+K27 -> 1845.4687 | L28: =+L26+L27 -> 0.4921875 | M28: =+M26+M27 -> -140.12695 | N28: =+N26+N27 -> 16603.5 | O28: =+O26+O27 -> 44593.5 | P28: =+P26+P27 -> 44593.5 | Q28: =+Q26+Q27 -> 44593.5 | AA28: 18120.06 | AB28: 0.0001 | AC28: 8 | AD28: 4.9909451 | AE28: 2.1178322 | AF28: 1
H29: Depreciación | J29: =-J23 -> 14355 | K29: =-K23 -> 14355 | L29: =-L23 -> 14355 | M29: =-M23 -> 14355 | N29: =-N23 -> 14355 | O29: =-O23 -> 435 | P29: =-P23 -> 435 | Q29: =-Q23 -> 435 | AA29: -2879.2 | AB29: 0.0001 | AC29: 9 | AD29: 4.9362686 | AE29: 2.1406667 | AF29: 1
A30: Año | B30: Utilización | C30: Producción unidades | H30: Amortización | J30: =-J24 -> 3425 | K30: =-K24 -> 3425 | L30: =-L24 -> 3425 | M30: =-M24 -> 3425 | N30: =-N24 -> 0 | O30: =-O24 -> 0 | P30: =-P24 -> 0 | Q30: =-Q24 -> 0 | S30: Ejemplo | AA30: 42758.59 | AB30: 0.0001 | AC30: 7 | AD30: 4.9811947 | AE30: 2.1696118 | AF30: 1
A31: 1 | B31: 0.5 | C31: =+B31*$B$13 -> 15000 | H31: Flujo de operación | J31: =+J28+J29+J30 -> 20761.625 | K31: =+K28+K29+K30 -> 19625.469 | L31: =+L28+L29+L30 -> 17780.492 | M31: =+M28+M29+M30 -> 17639.873 | N31: =+N28+N29+N30 -> 30958.5 | O31: =+O28+O29+O30 -> 45028.5 | P31: =+P28+P29+P30 -> 45028.5 | Q31: =+Q28+Q29+Q30 -> 45028.5 | AA31: 19543.07 | AB31: 0.0001 | AC31: 8 | AD31: 5.1922538 | AE31: 2.1925555 | AF31: 1
A32: 2 | B32: 0.55 | C32: =+B32*$B$13 -> 16500 | AA32: 45936.99 | AB32: 0.0001 | AC32: 7 | AD32: 5.2425849 | AE32: 2.1832031 | AF32: 1
A33: 3 | B33: 0.65 | C33: =+B33*$B$13 -> 19500 | H33: Flujo de caja libre | I33: =+I18+I31 -> -120200 | J33: =+J18+J31 -> 20011.625 | K33: =+K18+K31 -> 18125.469 | L33: =+L18+L31 -> 17030.492 | M33: =+M18+M31 -> 17639.873 | N33: =+N18+N31 -> 30958.5 | O33: =+O18+O31 -> 45028.5 | P33: =+P18+P31 -> 45028.5 | Q33: =+Q18+Q31 -> 86668.5 | AA33: 27769.62 | AB33: 0.0001 | AC33: 8 | AD33: 5.1556593 | AE33: 2.1379454 | AF33: 1
A34: 4 | B34: 0.7 | C34: =+B34*$B$13 -> 21000 | H34: Flujos descontados | I34: =+I33 -> -120200 | J34: =+J33/(1+B23)^J1 -> 17554.057 | K34: =+K33/(1+B23)^K1 -> 13946.96 | L34: =+L33/(1+B23)^L1 -> 11495.097 | M34: =+M33/(1+B23)^M1 -> 10444.221 | N34: =+N33/(1+B23)^N1 -> 16078.875 | O34: =+O33/(1+B23)^O1 -> 20514.379 | P34: =+P33/(1+B23)^P1 -> 17995.069 | Q34: =+Q33/(1+B23)^Q1 -> 30382.427 | AA34: 5286.71 | AB34: 0.0001 | AC34: 8 | AD34: 4.9601837 | AE34: 2.17695 | AF34: 1
A35: 5 | B35: 0.85 | C35: =+B35*$B$13 -> 25500 | H35: Flujos descontados Acum | I35: =+I34 -> -120200 | J35: =+J34+I35 -> -102645.94 | K35: =+K34+J35 -> -88698.983 | L35: =+L34+K35 -> -77203.886 | M35: =+M34+L35 -> -66759.665 | N35: =+N34+M35 -> -50680.79 | O35: =+O34+N35 -> -30166.412 | P35: =+P34+O35 -> -12171.342 | Q35: =+Q34+P35 -> 18211.085 | AA35: 40588.79 | AB35: 0.0001 | AC35: 7 | AD35: 5.0517448 | AE35: 2.1467607 | AF35: 1
A36: 6 | B36: 1 | C36: =+B36*$B$13 -> 30000 | H36: Valor de Liquidacion Anticipada de Activos (% del valor de compra) | J36: 0.6 | K36: 0.5 | L36: 0.4 | M36: 0.35 | N36: 0.3 | O36: 0.25 | P36: 0.15 | Q36: =10%*(8/Q1)^2 -> 0.1 | AA36: 8874.98 | AB36: 0.0001 | AC36: 8 | AD36: 4.8408119 | AE36: 2.2547545 | AF36: 1
A37: 7 | B37: 1 | C37: =+B37*$B$13 -> 30000 | H37: Liquidacion Anticipada de Maquinaria | J37: =+J36*$D$2 -> 41760 | K37: =+K36*$D$2 -> 34800 | L37: =+L36*$D$2 -> 27840 | M37: =+M36*$D$2 -> 24360 | N37: =+N36*$D$2 -> 20880 | O37: =+O36*$D$2 -> 17400 | P37: =+P36*$D$2 -> 10440 | Q37: =+Q36*$D$2 -> 6960 | AA37: 7444.68 | AB37: 0.0001 | AC37: 8 | AD37: 5.1032441 | AE37: 2.2893105 | AF37: 1
A38: 8 | B38: 1 | C38: =+B38*$B$13 -> 30000 | H38: Liquidacion Anticipada de Obras Civiles | J38: =-$I4--$I4*(J1/40) -> 16965 | K38: =-$I4--$I4*(K1/40) -> 16530 | L38: =-$I4--$I4*(L1/40) -> 16095 | M38: =-$I4--$I4*(M1/40) -> 15660 | N38: =-$I4--$I4*(N1/40) -> 15225 | O38: =-$I4--$I4*(O1/40) -> 14790 | P38: =-$I4--$I4*(P1/40) -> 14355 | Q38: =-$I4--$I4*(Q1/40) -> 13920 | AA38: 36300.23 | AB38: 0.0001 | AC38: 7 | AD38: 5.133048 | AE38: 2.1380637 | AF38: 1
H39: Liquidacion Anticipada de Terreno | J39: =+B4 -> 12000 | K39: =+J39 -> 12000 | L39: =+K39 -> 12000 | M39: =+L39 -> 12000 | N39: =+M39 -> 12000 | O39: =+N39 -> 12000 | P39: =+O39 -> 12000 | Q39: =+P39 -> 12000 | AA39: 3825.16 | AB39: 0.0001 | AC39: 8 | AD39: 4.8881399 | AE39: 2.2120424 | AF39: 1
H40: Liquidacion Anticipada Capital de Trabajo | J40: =-IF(J9<>0,J9,LOOKUP(2,1/($I$9:$Q$9<>0),$I$9:$Q$9))*J36 -> 450 | K40: =-IF(K9<>0,K9,LOOKUP(2,1/($I$9:$Q$9<>0),$I$9:$Q$9))*K36 -> 750 | L40: =-IF(L9<>0,L9,LOOKUP(2,1/($I$9:$Q$9<>0),$I$9:$Q$9))*L36 -> 300 | M40: =-IF(M9<>0,M9,LOOKUP(2,1/($I$9:$Q$9<>0),$I$9:$Q$9))*M36 -> 262.5 | N40: =-IF(N9<>0,N9,LOOKUP(2,1/($I$9:$Q$9<>0),$I$9:$Q$9))*N36 -> 225 | O40: =-IF(O9<>0,O9,LOOKUP(2,1/($I$9:$Q$9<>0),$I$9:$Q$9))*O36 -> 187.5 | P40: =-IF(P9<>0,P9,LOOKUP(2,1/($I$9:$Q$9<>0),$I$9:$Q$9))*P36 -> 112.5 | Q40: =-IF(Q9<>0,Q9,LOOKUP(2,1/($I$9:$Q$9<>0),$I$9:$Q$9))*Q36 -> 75 | AA40: 10401.38 | AB40: 0.0001 | AC40: 8 | AD40: 5.0015105 | AE40: 2.2094756 | AF40: 1
...

Sheet Depreciacion
B1: 1 | C1: 2 | D1: 3 | E1: 4 | F1: 5 | G1: 6 | H1: 7 | I1: 8 | J1: Valor Terminal contable
A2: Maquinaria | B2: ='Flujo de Caja'!D2/5 -> 13920 | C2: =+B2 -> 13920 | D2: =+C2 -> 13920 | E2: =+D2 -> 13920 | F2: =+E2 -> 13920 | J2: 0
A3: Obras civiles | B3: ='Flujo de Caja'!D3/40 -> 435 | C3: =+B3 -> 435 | D3: =+C3 -> 435 | E3: =+D3 -> 435 | F3: =+E3 -> 435 | G3: =+F3 -> 435 | H3: =+G3 -> 435 | I3: =+H3 -> 435 | J3: =35000-SUM(B3:I3) -> 31520
A4: Depreciacion | B4: =+B3+B2 -> 14355 | C4: =+C3+C2 -> 14355 | D4: =+D3+D2 -> 14355 | E4: =+E3+E2 -> 14355 | F4: =+F3+F2 -> 14355 | G4: =+G3+G2 -> 435 | H4: =+H3+H2 -> 435 | I4: =+I3+I2 -> 435
A6: Inversion Diferida
A7: Ingeniería del proyecto | B7: =+'Flujo de Caja'!D5/4 -> 2175 | C7: =+B7 -> 2175 | D7: =+C7 -> 2175 | E7: =+D7 -> 2175
A8: Gastos preoperacionales | B8: =+'Flujo de Caja'!B6/4 -> 1250 | C8: =+B8 -> 1250 | D8: =+C8 -> 1250 | E8: =+D8 -> 1250
A9: Amortizacion | B9: =+B8+B7 -> 3425 | C9: =+C8+C7 -> 3425 | D9: =+D8+D7 -> 3425 | E9: =+E8+E7 -> 3425 | F9: =+F8+F7 -> 0 | G9: =+G8+G7 -> 0 | H9: =+H8+H7 -> 0 | I9: =+I8+I7 -> 0
